<?xml version="1.0" ?>
<robot name="converted_robot">
   <link name="world">
      <inertial>
         <origin xyz="0.0 0.0 0.0" rpy="0.0 0.0 0.0"/>
         <mass value="0.0"/>
         <inertia ixx="0.0" iyy="0.0" izz="0.0" ixy="0" ixz="0" iyz="0"/>
      </inertial>
   </link>
   <link name="base">
      <inertial>
         <origin xyz="-3.4211304109885643e-06 -2.490354269956851e-08 0.0015607933514156045" rpy="-0.17751113049943767 -1.5707843937251857 -2.964091695409995"/>
         <mass value="102.0"/>
         <inertia ixx="0.17242001282942743" iyy="0.1466316728707274" izz="0.028716044382297204" ixy="0" ixz="0" iyz="0"/>
      </inertial>
      <visual name="top_base">
         <origin xyz="-1.727430576882212e-11 -3.036580521290373e-12 0.0020000000757601855" rpy="3.141592653589793 -1.5707963267948966 0.0"/>
         <geometry>
            <mesh filename="converted_top_base.stl"/>
         </geometry>
         <material name="white"/>
      </visual>
      <visual name="GSA_motor">
         <origin xyz="-0.03717447678724513 -1.2699288486519294e-06 -0.02039954286581345" rpy="2.064562682641896 -1.282378978223323 0.05188910277957115"/>
         <geometry>
            <mesh filename="converted_GSA_motor.stl"/>
         </geometry>
         <material name="white"/>
      </visual>
      <visual name="GSA_motor">
         <origin xyz="0.03682552321275487 -1.2699288486519294e-06 -0.02039954286581345" rpy="2.064562682641896 -1.282378978223323 0.05188910277957115"/>
         <geometry>
            <mesh filename="converted_GSA_motor.stl"/>
         </geometry>
         <material name="white"/>
      </visual>

      <collision>
         <geometry>
            <cylinder length="0.05" radius="0.04"/>
         </geometry>
         <origin xyz="-0.037 0 -0.022" rpy="0 0 0"/>
         <contact_coefficients mu="1" kp="1000.0" kd="1.0"/>
      </collision>
      <collision>
         <geometry>
            <cylinder length="0.05" radius="0.04"/>
         </geometry>
         <origin xyz="0.037 0 -0.022" rpy="0 0 0"/>
         <contact_coefficients mu="1" kp="1000.0" kd="1.0"/>
      </collision>
   </link>

   <link name="world2base_fixed_jointbody">
      <inertial>
         <origin xyz="0.0 0.0 0.0" rpy="0.0 0.0 0.0"/>
         <mass value="0.001"/>
         <inertia ixx="1e-09" iyy="1e-09" izz="1e-09" ixy="0" ixz="0" iyz="0"/>
      </inertial>
   </link>
   <joint type="fixed" name="world2base_fixed">
      <parent link="world"/>
      <child link="world2base_fixed_jointbody"/>
      <origin xyz="0.0 0.0 0.3685" rpy="0.0 0.0 0.0"/>
   </joint>
   <joint type="fixed" name="world2base_fixed_offset">
      <parent link="world2base_fixed_jointbody"/>
      <child link="base"/>
      <origin xyz="-0.0 -0.0 -0.0" rpy="0.0 0.0 0.0"/>
   </joint>
   <link name="left_leg1">
      <inertial>
         <origin xyz="-0.001452937585979903 0.01710854259181341 0.009885533891432676" rpy="-0.15176900399610038 -0.11560929427985034 2.3500658386485105"/>
         <mass value="1.0"/>
         <inertia ixx="0.00047926905851977604" iyy="0.000462327954156068" izz="0.0003410536632309082" ixy="0" ixz="0" iyz="0"/>
      </inertial>
      <visual name="leg1">
         <origin xyz="-0.001452937585979903 0.01710854259181341 0.009885533891432676" rpy="-0.15176900434746465 -0.11560931426673537 2.3500658417272327"/>
         <geometry>
            <mesh filename="converted_leg1.stl"/>
         </geometry>
         <material name="white"/>
      </visual>

      <collision>
         <origin xyz="0 0.01375 0.035" rpy="0 0 0"/>
         <geometry>
            <cylinder radius="0.022" length="0.02"/>
         </geometry>
      </collision>
      <collision>
         <origin xyz="0 0.015 0" rpy="1.5707963268 0 0"/> <!-- Rotation of 90 degrees about the X-axis -->
         <geometry>
            <cylinder radius="0.031" length="0.056"/>
         </geometry>
      </collision>

   </link>
   <link name="joint_left_leg1_jointbody">
      <inertial>
         <origin xyz="0.0 0.0 0.0" rpy="0.0 0.0 0.0"/>
         <mass value="0.001"/>
         <inertia ixx="1e-09" iyy="1e-09" izz="1e-09" ixy="0" ixz="0" iyz="0"/>
      </inertial>
   </link>
   <joint type="revolute" name="joint_left_leg1">
      <parent link="base"/>
      <child link="joint_left_leg1_jointbody"/>
      <origin xyz="-0.037 0.0 -0.095" rpy="0.0 0.0 0.0"/>
      <axis xyz="0.0 0.0 1.0"/>
      <limit lower="-1.5707963267948966" upper="1.5707963267948966" effort="100" velocity="100"/>
   </joint>
   <joint type="fixed" name="joint_left_leg1_offset">
      <parent link="joint_left_leg1_jointbody"/>
      <child link="left_leg1"/>
      <origin xyz="-0.0 -0.01375 -0.0" rpy="0.0 0.0 0.0"/>
   </joint>
   <link name="left_leg2">
      <inertial>
         <origin xyz="-0.06353323746651635 -1.0117572570772072e-05 -0.05040368781716482" rpy="0.0005981280417807397 -0.05157899065452698 -0.0006661205266934999"/>
         <mass value="1.0"/>
         <inertia ixx="0.002952437700856836" iyy="0.002736345424099424" izz="0.00043670614070026326" ixy="0" ixz="0" iyz="0"/>
      </inertial>
      <visual name="leg2">
         <origin xyz="-0.06353323746651635 -1.0117572570772072e-05 -0.05040368781716482" rpy="0.0005981280661683934 -0.051579022869918 -0.0006661205458496606"/>
         <geometry>
            <mesh filename="converted_leg2.stl"/>
         </geometry>
         <material name="white"/>
      </visual>

      <collision>
         <origin xyz="-0.068 0 0" rpy="0 1.5707963268 0"/> <!-- 90 degrees rotation around the Y-axis -->
         <geometry>
            <cylinder radius="0.04" length="0.042"/>
         </geometry>
      </collision>
      <collision>
         <origin xyz="-0.06525 0 -0.05" rpy="0 0 0"/> <!-- No rotation -->
         <geometry>
            <capsule radius="0.01" length="0.02"/>
         </geometry>
      </collision>
      <collision>
         <origin xyz="-0.06 0 -0.1" rpy="0 1.5707963268 0"/> <!-- 90 degrees rotation around the Y-axis -->
         <geometry>
            <cylinder radius="0.04" length="0.042"/>
         </geometry>
      </collision>
      <collision>
         <origin xyz="-0.033 0 -0.1" rpy="0 1.5707963268 0"/> <!-- 90 degrees rotation around the Y-axis -->
         <geometry>
            <cylinder radius="0.006" length="0.012"/>
         </geometry>
      </collision>

   </link>
   <link name="joint_left_leg12_jointbody">
      <inertial>
         <origin xyz="0.0 0.0 0.0" rpy="0.0 0.0 0.0"/>
         <mass value="0.001"/>
         <inertia ixx="1e-09" iyy="1e-09" izz="1e-09" ixy="0" ixz="0" iyz="0"/>
      </inertial>
   </link>
   <joint type="revolute" name="joint_left_leg12">
      <parent link="left_leg1"/>
      <child link="joint_left_leg12_jointbody"/>
      <origin xyz="0.0115 0.01375 0.0" rpy="0.0 0.0 0.0"/>
      <axis xyz="0.0 1.0 0.0"/>
      <limit lower="-0.872665" upper="0.174533" effort="100" velocity="100"/>
   </joint>
   <link name="joint_left_leg2_jointbody">
      <inertial>
         <origin xyz="0.0 0.0 0.0" rpy="0.0 0.0 0.0"/>
         <mass value="0.001"/>
         <inertia ixx="1e-09" iyy="1e-09" izz="1e-09" ixy="0" ixz="0" iyz="0"/>
      </inertial>
   </link>
   <joint type="revolute" name="joint_left_leg2">
      <parent link="joint_left_leg12_jointbody"/>
      <child link="joint_left_leg2_jointbody"/>
      <origin xyz="0.0115 0.01375 0.0" rpy="0.0 0.0 0.0"/>
      <axis xyz="-1.0 0.0 0.0"/>
      <limit lower="-2.967060" upper="2.967060" effort="100" velocity="100"/>
   </joint>
   <joint type="fixed" name="joint_left_leg2_offset">
      <parent link="joint_left_leg2_jointbody"/>
      <child link="left_leg2"/>
      <origin xyz="-0.0 -0.0 -0.0" rpy="0.0 0.0 0.0"/>
   </joint>
   <link name="left_leg3">
      <inertial>
         <origin xyz="-0.062377196123538585 -4.644821019518809e-05 -0.10008040953289711" rpy="1.0469517637872496 -0.005645692804368663 0.003260817465023935"/>
         <mass value="1.0"/>
         <inertia ixx="0.0007016859502857594" iyy="0.0004601204567843813" izz="0.0004579127751176568" ixy="0" ixz="0" iyz="0"/>
      </inertial>
      <visual name="leg3">
         <origin xyz="-0.062377196123538585 -4.644821019518809e-05 -0.10008040953289711" rpy="1.0469517638243213 -0.0056456965788584945 0.0032608109388136963"/>
         <geometry>
            <mesh filename="converted_leg3.stl"/>
         </geometry>
         <material name="white"/>
      </visual>

      <collision>
         <origin xyz="-0.06525 0 -0.05" rpy="0 0 0"/> <!-- No rotation -->
         <geometry>
            <capsule radius="0.01" length="0.02"/>
         </geometry>
      </collision>
      <collision>
         <origin xyz="-0.06 0 -0.1" rpy="0 1.5707963268 0"/> <!-- 90 degrees rotation around the Y-axis -->
         <geometry>
            <cylinder radius="0.04" length="0.042"/>
         </geometry>
      </collision>
      <collision>
         <origin xyz="-0.033 0 -0.1" rpy="0 1.5707963268 0"/> <!-- 90 degrees rotation around the Y-axis -->
         <geometry>
            <cylinder radius="0.006" length="0.012"/>
         </geometry>
      </collision>

   </link>
   <link name="joint_left_leg3_jointbody">
      <inertial>
         <origin xyz="0.0 0.0 0.0" rpy="0.0 0.0 0.0"/>
         <mass value="0.001"/>
         <inertia ixx="1e-09" iyy="1e-09" izz="1e-09" ixy="0" ixz="0" iyz="0"/>
      </inertial>
   </link>
   <joint type="revolute" name="joint_left_leg3">
      <parent link="left_leg2"/>
      <child link="joint_left_leg3_jointbody"/>
      <origin xyz="0.0 0.0 -0.1" rpy="0.0 0.0 0.0"/>
      <axis xyz="1.0 0.0 0.0"/>
      <limit lower="0" upper="2.268928" effort="100" velocity="100"/>
   </joint>
   <joint type="fixed" name="joint_left_leg3_offset">
      <parent link="joint_left_leg3_jointbody"/>
      <child link="left_leg3"/>
      <origin xyz="-0.0 -0.0 -0.0" rpy="0.0 0.0 0.0"/>
   </joint>
   <link name="left_foot">
      <inertial>
         <origin xyz="-3.376177828075782e-07 -0.016111475801689343 -0.06474004681919711" rpy="3.1403444956905995 -1.528381632682709 -1.569560431427483"/>
         <mass value="2.0"/>
         <inertia ixx="0.0023275568854970643" iyy="0.002117574063224331" izz="0.0004286806635036659" ixy="0" ixz="0" iyz="0"/>
      </inertial>
      <visual name="foot">
         <origin xyz="-6.752337760860577e-07 -0.01222295164580474 -0.05848009372299657" rpy="3.140201803154934 -1.5283193564154143 -1.5694446549316492"/>
         <geometry>
            <mesh filename="converted_foot.stl"/>
         </geometry>
         <material name="white"/>
      </visual>
      <visual name="sole">
         <origin xyz="-1.7895290986650519e-12 -0.019999999957573945 -0.07099999991539764" rpy="1.5707963267948966 -1.5707963267948966 0.0"/>
         <geometry>
            <mesh filename="converted_sole.stl"/>
         </geometry>
         <material name="white"/>
      </visual>

      <collision>
         <geometry>
            <box size="0.044 0.06 0.024"/>
         </geometry>
         <origin xyz="0 0 -0.053" rpy="0 0 0"/>
      </collision>

      <collision>
         <geometry>
            <cylinder length="0.034" radius="0.006"/>
         </geometry>
         <origin xyz="0 0.034 -0.06850" rpy="0 -1.5707963268 0"/>
      </collision>

      <collision>
         <geometry>
            <cylinder length="0.034" radius="0.006"/>
         </geometry>
         <origin xyz="0 -0.074 -0.06850" rpy="0 -1.5707963268 0"/>
      </collision>

      <collision>
         <geometry>
            <cylinder length="0.108" radius="0.006"/>
         </geometry>
         <origin xyz="0.017 -0.02 -0.06850" rpy="1.5707963268 0 0"/>
      </collision>

      <collision>
         <geometry>
            <cylinder length="0.108" radius="0.006"/>
         </geometry>
         <origin xyz="-0.017 -0.02 -0.06850" rpy="1.5707963268 0 0"/>
      </collision>

      <collision>
         <geometry>
            <sphere radius="0.006"/>
         </geometry>
         <origin xyz="-0.017 0.034 -0.06850" rpy="0 0 0"/>
      </collision>
      <collision>
         <geometry>
            <sphere radius="0.006"/>
         </geometry>
         <origin xyz="-0.017 -0.074 -0.06850" rpy="0 0 0"/>
      </collision>
      <collision>
         <geometry>
            <sphere radius="0.006"/>
         </geometry>
         <origin xyz="0.017 0.034 -0.06850" rpy="0 0 0"/>
      </collision>
      <collision>
         <geometry>
            <sphere radius="0.006"/>
         </geometry>
         <origin xyz="0.017 -0.074 -0.06850" rpy="0 0 0"/>
      </collision>
   </link>
   <link name="joint_left_foot_jointbody">
      <inertial>
         <origin xyz="0.0 0.0 0.0" rpy="0.0 0.0 0.0"/>
         <mass value="0.001"/>
         <inertia ixx="1e-09" iyy="1e-09" izz="1e-09" ixy="0" ixz="0" iyz="0"/>
      </inertial>
   </link>
   <joint type="revolute" name="joint_left_foot">
      <parent link="left_leg3"/>
      <child link="joint_left_foot_jointbody"/>
      <origin xyz="-0.06525 0.0 -0.1" rpy="0.0 0.0 0.0"/>
      <axis xyz="1.0 0.0 0.0"/>
      <limit lower="-1.134464" upper="1.396263" effort="100" velocity="100"/>
   </joint>
   <joint type="fixed" name="joint_left_foot_offset">
      <parent link="joint_left_foot_jointbody"/>
      <child link="left_foot"/>
      <origin xyz="-0.0 -0.0 -0.0" rpy="0.0 0.0 0.0"/>
   </joint>
   <link name="right_leg1">
      <inertial>
         <origin xyz="-0.001452937585979903 0.01710854259181341 0.009885533891432676" rpy="-0.15176900399610038 -0.11560929427985034 2.3500658386485105"/>
         <mass value="1.0"/>
         <inertia ixx="0.00047926905851977604" iyy="0.000462327954156068" izz="0.0003410536632309082" ixy="0" ixz="0" iyz="0"/>
      </inertial>
      <visual name="leg1">
         <origin xyz="-0.001452937585979903 0.01710854259181341 0.009885533891432676" rpy="-0.15176900434746465 -0.11560931426673537 2.3500658417272327"/>
         <geometry>
            <mesh filename="converted_leg1.stl"/>
         </geometry>
         <material name="white"/>
      </visual>

      <collision>
         <origin xyz="0 0.01375 0.035" rpy="0 0 0"/>
         <geometry>
            <cylinder radius="0.022" length="0.02"/>
         </geometry>
      </collision>
      <collision>
         <origin xyz="0 0.015 0" rpy="1.5707963268 0 0"/> <!-- Rotation of 90 degrees about the X-axis -->
         <geometry>
            <cylinder radius="0.031" length="0.056"/>
         </geometry>
      </collision>
   </link>
   <link name="joint_right_leg1_jointbody">
      <inertial>
         <origin xyz="0.0 0.0 0.0" rpy="0.0 0.0 0.0"/>
         <mass value="0.001"/>
         <inertia ixx="1e-09" iyy="1e-09" izz="1e-09" ixy="0" ixz="0" iyz="0"/>
      </inertial>
   </link>
   <joint type="revolute" name="joint_right_leg1">
      <parent link="base"/>
      <child link="joint_right_leg1_jointbody"/>
      <origin xyz="0.037 0.0 -0.095" rpy="0.0 0.0 3.141592653589793"/>
      <axis xyz="0.0 0.0 1.0"/>
      <limit lower="-0.785398" upper="0.785398" effort="100" velocity="100"/>
   </joint>
   <joint type="fixed" name="joint_right_leg1_offset">
      <parent link="joint_right_leg1_jointbody"/>
      <child link="right_leg1"/>
      <origin xyz="-0.0 -0.01375 -0.0" rpy="0.0 0.0 0.0"/>
   </joint>
   <link name="right_leg2">
      <inertial>
         <origin xyz="-0.06353323746651635 -1.0117572570772072e-05 -0.05040368781716482" rpy="0.0005981280417807397 -0.05157899065452698 -0.0006661205266934999"/>
         <mass value="1.0"/>
         <inertia ixx="0.002952437700856836" iyy="0.002736345424099424" izz="0.00043670614070026326" ixy="0" ixz="0" iyz="0"/>
      </inertial>
      <visual name="leg2">
         <origin xyz="-0.06353323746651635 -1.0117572570772072e-05 -0.05040368781716482" rpy="0.0005981280661683934 -0.051579022869918 -0.0006661205458496606"/>
         <geometry>
            <mesh filename="converted_leg2.stl"/>
         </geometry>
         <material name="white"/>
      </visual>

      <collision>
         <origin xyz="-0.068 0 0" rpy="0 1.5707963268 0"/> <!-- 90 degrees rotation around the Y-axis -->
         <geometry>
            <cylinder radius="0.04" length="0.042"/>
         </geometry>
      </collision>
      <collision>
         <origin xyz="-0.06525 0 -0.05" rpy="0 0 0"/> <!-- No rotation -->
         <geometry>
            <capsule radius="0.01" length="0.02"/>
         </geometry>
      </collision>
      <collision>
         <origin xyz="-0.06 0 -0.1" rpy="0 1.5707963268 0"/> <!-- 90 degrees rotation around the Y-axis -->
         <geometry>
            <cylinder radius="0.04" length="0.042"/>
         </geometry>
      </collision>
      <collision>
         <origin xyz="-0.033 0 -0.1" rpy="0 1.5707963268 0"/> <!-- 90 degrees rotation around the Y-axis -->
         <geometry>
            <cylinder radius="0.006" length="0.012"/>
         </geometry>
      </collision>

   </link>

   <link name="joint_right_leg12_jointbody">
      <inertial>
         <origin xyz="0.0 0.0 0.0" rpy="0.0 0.0 0.0"/>
         <mass value="0.001"/>
         <inertia ixx="1e-09" iyy="1e-09" izz="1e-09" ixy="0" ixz="0" iyz="0"/>
      </inertial>
   </link>
   <joint type="revolute" name="joint_right_leg12">
      <parent link="right_leg1"/>
      <child link="joint_right_leg12_jointbody"/>
      <origin xyz="0.0115 0.01375 0.0" rpy="0.0 0.0 0.0"/>
      <axis xyz="0.0 -1.0 0.0"/>
      <limit lower="-0.174533" upper="0.872665" effort="100" velocity="100"/>
   </joint>

   <link name="joint_right_leg2_jointbody">
      <inertial>
         <origin xyz="0.0 0.0 0.0" rpy="0.0 0.0 0.0"/>
         <mass value="0.001"/>
         <inertia ixx="1e-09" iyy="1e-09" izz="1e-09" ixy="0" ixz="0" iyz="0"/>
      </inertial>
   </link>
   <joint type="revolute" name="joint_right_leg2">
      <parent link="joint_right_leg12_jointbody"/>
      <child link="joint_right_leg2_jointbody"/>
      <origin xyz="0.0115 0.01375 0.0" rpy="0.0 0.0 0.0"/>
      <axis xyz="-1.0 0.0 0.0"/>
      <limit lower="-2.967060" upper="2.967060" effort="100" velocity="100"/>
   </joint>
   <joint type="fixed" name="joint_right_leg2_offset">
      <parent link="joint_right_leg2_jointbody"/>
      <child link="right_leg2"/>
      <origin xyz="-0.0 -0.0 -0.0" rpy="0.0 0.0 0.0"/>
   </joint>
   <link name="right_leg3">
      <inertial>
         <origin xyz="-0.062377196123538585 -4.644821019518809e-05 -0.10008040953289711" rpy="1.0469517637872496 -0.005645692804368663 0.003260817465023935"/>
         <mass value="1.0"/>
         <inertia ixx="0.0007016859502857594" iyy="0.0004601204567843813" izz="0.0004579127751176568" ixy="0" ixz="0" iyz="0"/>
      </inertial>
      <visual name="leg3">
         <origin xyz="-0.062377196123538585 -4.644821019518809e-05 -0.10008040953289711" rpy="1.0469517638243213 -0.0056456965788584945 0.0032608109388136963"/>
         <geometry>
            <mesh filename="converted_leg3.stl"/>
         </geometry>
         <material name="white"/>
      </visual>
      
      <collision>
         <origin xyz="-0.06525 0 -0.05" rpy="0 0 0"/> <!-- No rotation -->
         <geometry>
            <capsule radius="0.01" length="0.02"/>
         </geometry>
      </collision>
      <collision>
         <origin xyz="-0.06 0 -0.1" rpy="0 1.5707963268 0"/> <!-- 90 degrees rotation around the Y-axis -->
         <geometry>
            <cylinder radius="0.04" length="0.042"/>
         </geometry>
      </collision>
      <collision>
         <origin xyz="-0.033 0 -0.1" rpy="0 1.5707963268 0"/> <!-- 90 degrees rotation around the Y-axis -->
         <geometry>
            <cylinder radius="0.006" length="0.012"/>
         </geometry>
      </collision>

   </link>
   <link name="joint_right_leg3_jointbody">
      <inertial>
         <origin xyz="0.0 0.0 0.0" rpy="0.0 0.0 0.0"/>
         <mass value="0.001"/>
         <inertia ixx="1e-09" iyy="1e-09" izz="1e-09" ixy="0" ixz="0" iyz="0"/>
      </inertial>
   </link>
   <joint type="revolute" name="joint_right_leg3">
      <parent link="right_leg2"/>
      <child link="joint_right_leg3_jointbody"/>
      <origin xyz="0.0 0.0 -0.1" rpy="0.0 0.0 0.0"/>
      <axis xyz="1.0 0.0 0.0"/>
      <limit lower="0" upper="2.268928" effort="100" velocity="100"/>
   </joint>
   <joint type="fixed" name="joint_right_leg3_offset">
      <parent link="joint_right_leg3_jointbody"/>
      <child link="right_leg3"/>
      <origin xyz="-0.0 -0.0 -0.0" rpy="0.0 0.0 0.0"/>
   </joint>
   <link name="right_foot">
      <inertial>
         <origin xyz="3.376177828075782e-07 0.016111475801689343 -0.06474004681919711" rpy="-0.0012481578991933029 -1.528381632682709 1.57203222216231"/>
         <mass value="2.0"/>
         <inertia ixx="0.0023275568854970643" iyy="0.002117574063224331" izz="0.0004286806635036659" ixy="0" ixz="0" iyz="0"/>
      </inertial>
      <visual name="foot">
         <origin xyz="6.752337760860577e-07 0.01222295164580474 -0.05848009372299657" rpy="3.140201803154934 -1.5283193564154143 1.572147998658144"/>
         <geometry>
            <mesh filename="converted_foot.stl"/>
         </geometry>
         <material name="white"/>
      </visual>
      <visual name="sole">
         <origin xyz="1.7895290986650519e-12 0.019999999957573945 -0.07099999991539764" rpy="-1.5707963267948966 -1.5707963267948966 0.0"/>
         <geometry>
            <mesh filename="converted_sole.stl"/>
         </geometry>
         <material name="white"/>
      </visual>

            <collision>
         <geometry>
            <box size="0.044 0.06 0.024"/>
         </geometry>
         <origin xyz="0 0 -0.053" rpy="0 0 0"/>
      </collision>

      <collision>
         <geometry>
            <cylinder length="0.034" radius="0.006"/>
         </geometry>
         <origin xyz="0 -0.034 -0.06850" rpy="0 -1.5707963268 0"/>
      </collision>

      <collision>
         <geometry>
            <cylinder length="0.034" radius="0.006"/>
         </geometry>
         <origin xyz="0 0.074 -0.06850" rpy="0 -1.5707963268 0"/>
      </collision>

      <collision>
         <geometry>
            <cylinder length="0.108" radius="0.006"/>
         </geometry>
         <origin xyz="0.017 0.02 -0.06850" rpy="1.5707963268 0 0"/>
      </collision>

      <collision>
         <geometry>
            <cylinder length="0.108" radius="0.006"/>
         </geometry>
         <origin xyz="-0.017 0.02 -0.06850" rpy="1.5707963268 0 0"/>
      </collision>

      <collision>
         <geometry>
            <sphere radius="0.006"/>
         </geometry>
         <origin xyz="-0.017 -0.034 -0.06850" rpy="0 0 0"/>
      </collision>
      <collision>
         <geometry>
            <sphere radius="0.006"/>
         </geometry>
         <origin xyz="-0.017 0.074 -0.06850" rpy="0 0 0"/>
      </collision>
      <collision>
         <geometry>
            <sphere radius="0.006"/>
         </geometry>
         <origin xyz="0.017 -0.034 -0.06850" rpy="0 0 0"/>
      </collision>
      <collision>
         <geometry>
            <sphere radius="0.006"/>
         </geometry>
         <origin xyz="0.017 0.074 -0.06850" rpy="0 0 0"/>
      </collision>

   </link>
   <link name="joint_right_foot_jointbody">
      <inertial>
         <origin xyz="0.0 0.0 0.0" rpy="0.0 0.0 0.0"/>
         <mass value="0.001"/>
         <inertia ixx="1e-09" iyy="1e-09" izz="1e-09" ixy="0" ixz="0" iyz="0"/>
      </inertial>
   </link>
   <joint type="revolute" name="joint_right_foot">
      <parent link="right_leg3"/>
      <child link="joint_right_foot_jointbody"/>
      <origin xyz="-0.06525 0.0 -0.1" rpy="0.0 0.0 0.0"/>
      <axis xyz="1.0 0.0 0.0"/>
      <limit lower="-1.134464" upper="1.396263" effort="100" velocity="100"/>
   </joint>
   <joint type="fixed" name="joint_right_foot_offset">
      <parent link="joint_right_foot_jointbody"/>
      <child link="right_foot"/>
      <origin xyz="-0.0 -0.0 -0.0" rpy="0.0 0.0 0.0"/>
   </joint>
   <material name="white">
      <color rgba="1 1 1 1"/>
   </material>
</robot>
